Workbook

Sheet README
A1: PRP 2569 — analysis workbook (v2 of the full report)
A2: Source | B2: Built from the tables of the draft '2.PRP_รายงานฉบับสมบูรณ์ 2569 [DRAFT].docx'. No .xlsx was supplied with the draft.
A3: Status colours | B3: Black = value recorded in the draft. Bold red = [Place Holder] (not measured / assumed; must be replaced before publication). Yellow cells = editable inputs (emission factors, price ratio r).
A4: Strength_raw | B4: Per-specimen compressive strength (MPa). Three draft cells have a number but no original record: they are NOT in the specimen columns (so AVERAGE/STDEV ignore them); their draft values are listed in the red 'PH' columns.
A5: Strength_summary | B5: Live formulas: n, mean, SD, CV, difference to the reported mean, and 28-d % change vs control.
A6: Density / Absorption | B6: Per-specimen density = mass / volume and absorption = (wet-dry)/dry x 100 (formulas).
A7: Maturity | B7: EN 1992-1-1 maturity factor beta(t)=exp{s[1-(28/t)^0.5]}: s is a yellow input; compare predicted with measured f(t)/f(28).
A8: LCA | B8: Screening cradle-to-gate GWP (functional unit 1 m3 of block). Emission factors are ASSUMED (yellow, red); change them and every result updates.
A9: Cost | B9: Relative material cost vs RA as a function of the biochar price ratio r (yellow input).
A10: BPN_PLACEHOLDER | B10: Hypothetical British Pendulum Numbers (all red). NOT measurements.
A11: Charts | B11: Native Excel charts built from the sheets above.
A12: Reproducibility | B12: All numbers are produced by the scripts in report/scripts (seeds fixed). See report/docs/CHANGELOG_and_review_notes.md.

Sheet Strength_raw
A1: series | B1: mix | C1: age_d | D1: spec1_MPa | E1: spec2_MPa | F1: spec3_MPa | G1: reported_mean | H1: PH spec1 | I1: PH spec2 | J1: PH spec3
A2: I | B2: NA | C2: 7 | D2: 56 | E2: 69 | F2: 72 | G2: 65.7
A3: I | B3: NA | C3: 14 | E3: 80 | F3: 82 | G3: 81.06 | H3: 81
A4: I | B4: NA | C4: 28 | D4: 89 | E4: 84 | F4: 101 | G4: 91.54
A5: I | B5: RA | C5: 7 | D5: 29 | E5: 32 | G5: 30.78 | J5: 30
A6: I | B6: RA | C6: 14 | D6: 43 | F6: 44 | G6: 43.44 | I6: 44
A7: I | B7: RA | C7: 28 | D7: 54 | E7: 63 | F7: 65 | G7: 60.46
A8: I | B8: Rab5 | C8: 7 | D8: 36 | E8: 39 | F8: 43 | G8: 39.15
A9: I | B9: Rab5 | C9: 14 | D9: 41 | E9: 41 | F9: 46 | G9: 42.63
A10: I | B10: Rab5 | C10: 28 | D10: 51 | E10: 54 | F10: 51 | G10: 51.85
A11: I | B11: Rab10 | C11: 7 | D11: 26 | E11: 29 | F11: 28 | G11: 27.72
A12: I | B12: Rab10 | C12: 14 | D12: 41 | E12: 35 | F12: 38 | G12: 38.26
A13: I | B13: Rab10 | C13: 28 | D13: 44 | E13: 38 | F13: 36 | G13: 39.37
A14: I | B14: Rab15 | C14: 7 | D14: 27 | E14: 28 | F14: 32 | G14: 29.02
A15: I | B15: Rab15 | C15: 14 | D15: 37 | E15: 34 | F15: 35 | G15: 35.37
A16: I | B16: Rab15 | C16: 28 | D16: 37 | E16: 40 | F16: 38 | G16: 37.93
A17: II | B17: RCA0 | C17: 7 | D17: 22.81 | E17: 23.07 | F17: 24.13 | G17: 23.33
A18: II | B18: RCA0 | C18: 14 | D18: 41.99 | E18: 45.27 | F18: 54.05 | G18: 47.1
... A28: II | B28: RCA15 | C28: 28 | D28: 61.58 | E28: 62.44 | F28: 62.55 | G28: 62.19

Sheet Strength_summary
A1: series | B1: mix | C1: age_d | D1: n | E1: mean (recomputed) | F1: SD | G1: CV % | H1: reported mean | I1: recomputed - reported | J1: 28-d % vs series control
A2: =Strength_raw!A2 | B2: =Strength_raw!B2 | C2: =Strength_raw!C2 | D2: =COUNT(Strength_raw!D2:F2) | E2: =AVERAGE(Strength_raw!D2:F2) | F2: =STDEV(Strength_raw!D2:F2) | G2: =F2/E2*100 | H2: =Strength_raw!G2 | I2: =E2-H2
A3: =Strength_raw!A3 | B3: =Strength_raw!B3 | C3: =Strength_raw!C3 | D3: =COUNT(Strength_raw!D3:F3) | E3: =AVERAGE(Strength_raw!D3:F3) | F3: =STDEV(Strength_raw!D3:F3) | G3: =F3/E3*100 | H3: =Strength_raw!G3 | I3: =E3-H3
A4: =Strength_raw!A4 | B4: =Strength_raw!B4 | C4: =Strength_raw!C4 | D4: =COUNT(Strength_raw!D4:F4) | E4: =AVERAGE(Strength_raw!D4:F4) | F4: =STDEV(Strength_raw!D4:F4) | G4: =F4/E4*100 | H4: =Strength_raw!G4 | I4: =E4-H4 | J4: =(H4/Strength_raw!G7-1)*100
A5: =Strength_raw!A5 | B5: =Strength_raw!B5 | C5: =Strength_raw!C5 | D5: =COUNT(Strength_raw!D5:F5) | E5: =AVERAGE(Strength_raw!D5:F5) | F5: =STDEV(Strength_raw!D5:F5) | G5: =F5/E5*100 | H5: =Strength_raw!G5 | I5: =E5-H5
A6: =Strength_raw!A6 | B6: =Strength_raw!B6 | C6: =Strength_raw!C6 | D6: =COUNT(Strength_raw!D6:F6) | E6: =AVERAGE(Strength_raw!D6:F6) | F6: =STDEV(Strength_raw!D6:F6) | G6: =F6/E6*100 | H6: =Strength_raw!G6 | I6: =E6-H6
A7: =Strength_raw!A7 | B7: =Strength_raw!B7 | C7: =Strength_raw!C7 | D7: =COUNT(Strength_raw!D7:F7) | E7: =AVERAGE(Strength_raw!D7:F7) | F7: =STDEV(Strength_raw!D7:F7) | G7: =F7/E7*100 | H7: =Strength_raw!G7 | I7: =E7-H7 | J7: =(H7/Strength_raw!G7-1)*100
A8: =Strength_raw!A8 | B8: =Strength_raw!B8 | C8: =Strength_raw!C8 | D8: =COUNT(Strength_raw!D8:F8) | E8: =AVERAGE(Strength_raw!D8:F8) | F8: =STDEV(Strength_raw!D8:F8) | G8: =F8/E8*100 | H8: =Strength_raw!G8 | I8: =E8-H8
A9: =Strength_raw!A9 | B9: =Strength_raw!B9 | C9: =Strength_raw!C9 | D9: =COUNT(Strength_raw!D9:F9) | E9: =AVERAGE(Strength_raw!D9:F9) | F9: =STDEV(Strength_raw!D9:F9) | G9: =F9/E9*100 | H9: =Strength_raw!G9 | I9: =E9-H9
A10: =Strength_raw!A10 | B10: =Strength_raw!B10 | C10: =Strength_raw!C10 | D10: =COUNT(Strength_raw!D10:F10) | E10: =AVERAGE(Strength_raw!D10:F10) | F10: =STDEV(Strength_raw!D10:F10) | G10: =F10/E10*100 | H10: =Strength_raw!G10 | I10: =E10-H10 | J10: =(H10/Strength_raw!G7-1)*100
A11: =Strength_raw!A11 | B11: =Strength_raw!B11 | C11: =Strength_raw!C11 | D11: =COUNT(Strength_raw!D11:F11) | E11: =AVERAGE(Strength_raw!D11:F11) | F11: =STDEV(Strength_raw!D11:F11) | G11: =F11/E11*100 | H11: =Strength_raw!G11 | I11: =E11-H11
A12: =Strength_raw!A12 | B12: =Strength_raw!B12 | C12: =Strength_raw!C12 | D12: =COUNT(Strength_raw!D12:F12) | E12: =AVERAGE(Strength_raw!D12:F12) | F12: =STDEV(Strength_raw!D12:F12) | G12: =F12/E12*100 | H12: =Strength_raw!G12 | I12: =E12-H12
A13: =Strength_raw!A13 | B13: =Strength_raw!B13 | C13: =Strength_raw!C13 | D13: =COUNT(Strength_raw!D13:F13) | E13: =AVERAGE(Strength_raw!D13:F13) | F13: =STDEV(Strength_raw!D13:F13) | G13: =F13/E13*100 | H13: =Strength_raw!G13 | I13: =E13-H13 | J13: =(H13/Strength_raw!G7-1)*100
A14: =Strength_raw!A14 | B14: =Strength_raw!B14 | C14: =Strength_raw!C14 | D14: =COUNT(Strength_raw!D14:F14) | E14: =AVERAGE(Strength_raw!D14:F14) | F14: =STDEV(Strength_raw!D14:F14) | G14: =F14/E14*100 | H14: =Strength_raw!G14 | I14: =E14-H14
A15: =Strength_raw!A15 | B15: =Strength_raw!B15 | C15: =Strength_raw!C15 | D15: =COUNT(Strength_raw!D15:F15) | E15: =AVERAGE(Strength_raw!D15:F15) | F15: =STDEV(Strength_raw!D15:F15) | G15: =F15/E15*100 | H15: =Strength_raw!G15 | I15: =E15-H15
A16: =Strength_raw!A16 | B16: =Strength_raw!B16 | C16: =Strength_raw!C16 | D16: =COUNT(Strength_raw!D16:F16) | E16: =AVERAGE(Strength_raw!D16:F16) | F16: =STDEV(Strength_raw!D16:F16) | G16: =F16/E16*100 | H16: =Strength_raw!G16 | I16: =E16-H16 | J16: =(H16/Strength_raw!G7-1)*100
A17: =Strength_raw!A17 | B17: =Strength_raw!B17 | C17: =Strength_raw!C17 | D17: =COUNT(Strength_raw!D17:F17) | E17: =AVERAGE(Strength_raw!D17:F17) | F17: =STDEV(Strength_raw!D17:F17) | G17: =F17/E17*100 | H17: =Strength_raw!G17 | I17: =E17-H17
A18: =Strength_raw!A18 | B18: =Strength_raw!B18 | C18: =Strength_raw!C18 | D18: =COUNT(Strength_raw!D18:F18) | E18: =AVERAGE(Strength_raw!D18:F18) | F18: =STDEV(Strength_raw!D18:F18) | G18: =F18/E18*100 | H18: =Strength_raw!G18 | I18: =E18-H18
A19: =Strength_raw!A19 | B19: =Strength_raw!B19 | C19: =Strength_raw!C19 | D19: =COUNT(Strength_raw!D19:F19) | E19: =AVERAGE(Strength_raw!D19:F19) | F19: =STDEV(Strength_raw!D19:F19) | G19: =F19/E19*100 | H19: =Strength_raw!G19 | I19: =E19-H19 | J19: =(H19/Strength_raw!G19-1)*100
A20: =Strength_raw!A20 | B20: =Strength_raw!B20 | C20: =Strength_raw!C20 | D20: =COUNT(Strength_raw!D20:F20) | E20: =AVERAGE(Strength_raw!D20:F20) | F20: =STDEV(Strength_raw!D20:F20) | G20: =F20/E20*100 | H20: =Strength_raw!G20 | I20: =E20-H20
A21: =Strength_raw!A21 | B21: =Strength_raw!B21 | C21: =Strength_raw!C21 | D21: =COUNT(Strength_raw!D21:F21) | E21: =AVERAGE(Strength_raw!D21:F21) | F21: =STDEV(Strength_raw!D21:F21) | G21: =F21/E21*100 | H21: =Strength_raw!G21 | I21: =E21-H21
A22: =Strength_raw!A22 | B22: =Strength_raw!B22 | C22: =Strength_raw!C22 | D22: =COUNT(Strength_raw!D22:F22) | E22: =AVERAGE(Strength_raw!D22:F22) | F22: =STDEV(Strength_raw!D22:F22) | G22: =F22/E22*100 | H22: =Strength_raw!G22 | I22: =E22-H22 | J22: =(H22/Strength_raw!G19-1)*100
A23: =Strength_raw!A23 | B23: =Strength_raw!B23 | C23: =Strength_raw!C23 | D23: =COUNT(Strength_raw!D23:F23) | E23: =AVERAGE(Strength_raw!D23:F23) | F23: =STDEV(Strength_raw!D23:F23) | G23: =F23/E23*100 | H23: =Strength_raw!G23 | I23: =E23-H23
A24: =Strength_raw!A24 | B24: =Strength_raw!B24 | C24: =Strength_raw!C24 | D24: =COUNT(Strength_raw!D24:F24) | E24: =AVERAGE(Strength_raw!D24:F24) | F24: =STDEV(Strength_raw!D24:F24) | G24: =F24/E24*100 | H24: =Strength_raw!G24 | I24: =E24-H24
A25: =Strength_raw!A25 | B25: =Strength_raw!B25 | C25: =Strength_raw!C25 | D25: =COUNT(Strength_raw!D25:F25) | E25: =AVERAGE(Strength_raw!D25:F25) | F25: =STDEV(Strength_raw!D25:F25) | G25: =F25/E25*100 | H25: =Strength_raw!G25 | I25: =E25-H25 | J25: =(H25/Strength_raw!G19-1)*100
A26: =Strength_raw!A26 | B26: =Strength_raw!B26 | C26: =Strength_raw!C26 | D26: =COUNT(Strength_raw!D26:F26) | E26: =AVERAGE(Strength_raw!D26:F26) | F26: =STDEV(Strength_raw!D26:F26) | G26: =F26/E26*100 | H26: =Strength_raw!G26 | I26: =E26-H26
A27: =Strength_raw!A27 | B27: =Strength_raw!B27 | C27: =Strength_raw!C27 | D27: =COUNT(Strength_raw!D27:F27) | E27: =AVERAGE(Strength_raw!D27:F27) | F27: =STDEV(Strength_raw!D27:F27) | G27: =F27/E27*100 | H27: =Strength_raw!G27 | I27: =E27-H27
A28: =Strength_raw!A28 | B28: =Strength_raw!B28 | C28: =Strength_raw!C28 | D28: =COUNT(Strength_raw!D28:F28) | E28: =AVERAGE(Strength_raw!D28:F28) | F28: =STDEV(Strength_raw!D28:F28) | G28: =F28/E28*100 | H28: =Strength_raw!G28 | I28: =E28-H28 | J28: =(H28/Strength_raw!G19-1)*100
A31: 28-d reported mean (for chart)
B32: NA | C32: =Strength_raw!G4
B33: RA | C33: =Strength_raw!G7
B34: Rab5 | C34: =Strength_raw!G10
B35: Rab10 | C35: =Strength_raw!G13
B36: Rab15 | C36: =Strength_raw!G16
B37: RCA0 | C37: =Strength_raw!G19
B38: RCA5 | C38: =Strength_raw!G22
B39: RCA10 | C39: =Strength_raw!G25
B40: RCA15 | C40: =Strength_raw!G28

Sheet Density
A1: mix | B1: age_d | C1: mass_kg | D1: volume_m3 | E1: density (formula, kg/m3) | F1: density printed in draft | G1: reported mean
A2: NA | B2: 7 | C2: 3.28 | D2: 0.00156 | E2: =C2/D2 | F2: 2103 | G2: 2137
A3: NA | B3: 7 | C3: 3.33 | D3: 0.00156 | E3: =C3/D3 | F3: 2135
A4: NA | B4: 7 | C4: 3.39 | D4: 0.00156 | E4: =C4/D4 | F4: 2173
A5: NA | B5: 14 | C5: 3.62 | D5: 0.00156 | E5: =C5/D5 | F5: 2321 | G5: 2308
A6: NA | B6: 14 | C6: 3.62 | D6: 0.00156 | E6: =C6/D6 | F6: 2321
A7: NA | B7: 14 | C7: 3.56 | D7: 0.00156 | E7: =C7/D7 | F7: 2282
A8: NA | B8: 28 | C8: 3.54 | D8: 0.00156 | E8: =C8/D8 | F8: 2269 | G8: 2284
A9: NA | B9: 28 | C9: 3.54 | D9: 0.00156 | E9: =C9/D9 | F9: 2269
A10: NA | B10: 28 | C10: 3.61 | D10: 0.00156 | E10: =C10/D10 | F10: 2314
A11: RA | B11: 7 | C11: 3.25 | D11: 0.00156 | E11: =C11/D11 | F11: 2083 | G11: 2125
A12: RA | B12: 7 | C12: 3.38 | D12: 0.00156 | E12: =C12/D12 | F12: 2167
A13: RA | B13: 7 | C13: 3.25 | D13: 0.00156 | E13: =C13/D13 | F13: 2083
A14: RA | B14: 14 | C14: 3.45 | D14: 0.00156 | E14: =C14/D14 | F14: 2212 | G14: 2224
A15: RA | B15: 14 | C15: 3.42 | D15: 0.00156 | E15: =C15/D15 | F15: 2192
A16: RA | B16: 14 | C16: 3.54 | D16: 0.00156 | E16: =C16/D16 | F16: 2269
A17: RA | B17: 28 | C17: 3.48 | D17: 0.00156 | E17: =C17/D17 | F17: 2231 | G17: 2235
A18: RA | B18: 28 | C18: 3.46 | D18: 0.00156 | E18: =C18/D18 | F18: 2218
A19: RA | B19: 28 | C19: 3.52 | D19: 0.00156 | E19: =C19/D19 | F19: 2256
A20: Rab5 | B20: 7 | C20: 3.19 | D20: 0.00156 | E20: =C20/D20 | F20: 2045 | G20: 2073
A21: Rab5 | B21: 7 | C21: 3.28 | D21: 0.00156 | E21: =C21/D21 | F21: 2103
A22: Rab5 | B22: 7 | C22: 3.23 | D22: 0.00156 | E22: =C22/D22 | F22: 2071
A23: Rab5 | B23: 14 | C23: 3.29 | D23: 0.00156 | E23: =C23/D23 | F23: 2109 | G23: 2053
A24: Rab5 | B24: 14 | C24: 3.19 | D24: 0.00156 | E24: =C24/D24 | F24: 2045
A25: Rab5 | B25: 14 | C25: 3.13 | D25: 0.00156 | E25: =C25/D25 | F25: 2006
A26: Rab5 | B26: 28 | C26: 3.39 | D26: 0.00156 | E26: =C26/D26 | F26: 2173 | G26: 2150
A27: Rab5 | B27: 28 | C27: 3.38 | D27: 0.00156 | E27: =C27/D27 | F27: 2167
A28: Rab5 | B28: 28 | C28: 3.29 | D28: 0.00156 | E28: =C28/D28 | F28: 2109
A29: Rab10 | B29: 7 | C29: 3.04 | D29: 0.00156 | E29: =C29/D29 | F29: 1949 | G29: 1996
A30: Rab10 | B30: 7 | C30: 3.15 | D30: 0.00156 | E30: =C30/D30 | F30: 2019
A31: Rab10 | B31: 7 | C31: 3.15 | D31: 0.00156 | E31: =C31/D31 | F31: 2019
A32: Rab10 | B32: 14 | C32: 3.2 | D32: 0.00156 | E32: =C32/D32 | F32: 2051 | G32: 2006
A33: Rab10 | B33: 14 | C33: 3.15 | D33: 0.00156 | E33: =C33/D33 | F33: 2019
A34: Rab10 | B34: 14 | C34: 3.04 | D34: 0.00156 | E34: =C34/D34 | F34: 1949
A35: Rab10 | B35: 28 | C35: 3.23 | D35: 0.00156 | E35: =C35/D35 | F35: 2071 | G35: 2011
A36: Rab10 | B36: 28 | C36: 3.12 | D36: 0.00156 | E36: =C36/D36 | F36: 2000
A37: Rab10 | B37: 28 | C37: 3.06 | D37: 0.00156 | E37: =C37/D37 | F37: 1962
A38: Rab15 | B38: 7 | C38: 3.21 | D38: 0.00156 | E38: =C38/D38 | F38: 2058 | G38: 2047
A39: Rab15 | B39: 7 | C39: 3.17 | D39: 0.00156 | E39: =C39/D39 | F39: 2032
A40: Rab15 | B40: 7 | C40: 3.2 | D40: 0.00156 | E40: =C40/D40 | F40: 2051
...

Sheet Absorption
A1: series | B1: mix | C1: age_d | D1: specimen | E1: wet_kg | F1: dry_kg | G1: absorption % (formula) | H1: absorption % printed | I1: flag
A2: I | B2: Rab5 | C2: 14 | D2: 1 | E2: 3.31 | F2: 3.28 | G2: =(E2-F2)/F2*100 | H2: 0.91
A3: I | B3: Rab5 | C3: 14 | D3: 2 | E3: 3.39 | F3: 3.35 | G3: =(E3-F3)/F3*100 | H3: 1.19
A4: I | B4: Rab5 | C4: 14 | D4: 3 | E4: 3.39 | F4: 3.36 | G4: =(E4-F4)/F4*100 | H4: 0.89
A5: I | B5: Rab5 | C5: 28 | D5: 1 | E5: 3.41 | F5: 3.39 | G5: =(E5-F5)/F5*100 | H5: 0.59
A6: I | B6: Rab5 | C6: 28 | D6: 2 | E6: 3.41 | F6: 3.38 | G6: =(E6-F6)/F6*100 | H6: 0.89
A7: I | B7: Rab5 | C7: 28 | D7: 3 | E7: 3.31 | F7: 3.29 | G7: =(E7-F7)/F7*100 | H7: 0.61
A8: II | B8: RCA0 | C8: 7 | D8: s1 | H8: 1.16
A9: II | B9: RCA0 | C9: 7 | D9: s2 | H9: 0.9
A10: II | B10: RCA0 | C10: 7 | D10: s3 | H10: 0.91
A11: II | B11: RCA0 | C11: 14 | D11: s1 | H11: 1.18
A12: II | B12: RCA0 | C12: 14 | D12: s2 | H12: 0.9
A13: II | B13: RCA0 | C13: 14 | D13: s3 | H13: 0.9
A14: II | B14: RCA0 | C14: 28 | D14: s1 | H14: 0.87
A15: II | B15: RCA0 | C15: 28 | D15: s2 | H15: 0.89
A16: II | B16: RCA0 | C16: 28 | D16: s3 | H16: 0.89
A17: II | B17: RCA5 | C17: 7 | D17: s1 | H17: 0.6
A18: II | B18: RCA5 | C18: 7 | D18: s2 | H18: 0.6
A19: II | B19: RCA5 | C19: 7 | D19: s3 | H19: 0.59
... A28: II | B28: RCA10 | C28: 7 | D28: s3 | H28: 0.91
A29: II | B29: RCA10 | C29: 14 | D29: s1 | H29: 2.69 | I29: re-test needed (see Appendix B)
A30: II | B30: RCA10 | C30: 14 | D30: s2 | H30: 2.74 | I30: re-test needed (see Appendix B)
A31: II | B31: RCA10 | C31: 14 | D31: s3 | H31: 2.77 | I31: re-test needed (see Appendix B)
A32: II | B32: RCA10 | C32: 28 | D32: s1 | H32: 1.47
A33: II | B33: RCA10 | C33: 28 | D33: s2 | H33: 1.52
A34: II | B34: RCA10 | C34: 28 | D34: s3 | H34: 1.53
A35: II | B35: RCA15 | C35: 7 | D35: s1 | H35: 0.29
A36: II | B36: RCA15 | C36: 7 | D36: s2 | H36: 0.3
A37: II | B37: RCA15 | C37: 7 | D37: s3 | H37: 0.61
A38: II | B38: RCA15 | C38: 14 | D38: s1 | H38: 2.69 | I38: re-test needed (see Appendix B)
A39: II | B39: RCA15 | C39: 14 | D39: s2 | H39: 2.4 | I39: re-test needed (see Appendix B)
A40: II | B40: RCA15 | C40: 14 | D40: s3 | H40: 2.68 | I40: re-test needed (see Appendix B)
A41: II | B41: RCA15 | C41: 28 | D41: s1 | H41: 0.29 | I41: re-test needed (see Appendix B)
A42: II | B42: RCA15 | C42: 28 | D42: s2 | H42: 0.3 | I42: re-test needed (see Appendix B)
A43: II | B43: RCA15 | C43: 28 | D43: s3 | H43: 0.61 | I43: re-test needed (see Appendix B)

Sheet Maturity
A1: mix | B1: f7/f28 measured | C1: f14/f28 measured | D1: s (input) | E1: beta(7) model | F1: beta(14) model | G1: 7-d residual | H1: 14-d residual
A2: NA | B2: 0.71771903 | C2: 0.88551453 | D2: 0.326 | E2: =EXP(D2*(1-(28/7)^0.5)) | F2: =EXP(D2*(1-(28/14)^0.5)) | G2: =B2-E2 | H2: =C2-F2
A3: RA | B3: 0.50909692 | C3: 0.71849156 | D3: 0.693 | E3: =EXP(D3*(1-(28/7)^0.5)) | F3: =EXP(D3*(1-(28/14)^0.5)) | G3: =B3-E3 | H3: =C3-F3
A4: Rab10 | B4: 0.70408941 | C4: 0.97180594 | D4: 0.31 | E4: =EXP(D4*(1-(28/7)^0.5)) | F4: =EXP(D4*(1-(28/14)^0.5)) | G4: =B4-E4 | H4: =C4-F4
A5: Rab15 | B5: 0.76509359 | C5: 0.93250725 | D5: 0.253 | E5: =EXP(D5*(1-(28/7)^0.5)) | F5: =EXP(D5*(1-(28/14)^0.5)) | G5: =B5-E5 | H5: =C5-F5
A6: Rab5 | B6: 0.75506268 | C6: 0.82217936 | D6: 0.309 | E6: =EXP(D6*(1-(28/7)^0.5)) | F6: =EXP(D6*(1-(28/14)^0.5)) | G6: =B6-E6 | H6: =C6-F6
A7: RCA0 | B7: 0.42089121 | C7: 0.84972037 | D7: 0.796 | E7: =EXP(D7*(1-(28/7)^0.5)) | F7: =EXP(D7*(1-(28/14)^0.5)) | G7: =B7-E7 | H7: =C7-F7
A8: RCA10 | B8: 0.46348223 | C8: 0.8708836 | D8: 0.705 | E8: =EXP(D8*(1-(28/7)^0.5)) | F8: =EXP(D8*(1-(28/14)^0.5)) | G8: =B8-E8 | H8: =C8-F8
A9: RCA15 | B9: 0.55121402 | C9: 0.88084901 | D9: 0.553 | E9: =EXP(D9*(1-(28/7)^0.5)) | F9: =EXP(D9*(1-(28/14)^0.5)) | G9: =B9-E9 | H9: =C9-F9
A10: RCA5 | B10: 0.42640364 | C10: 0.82144664 | D10: 0.797 | E10: =EXP(D10*(1-(28/7)^0.5)) | F10: =EXP(D10*(1-(28/14)^0.5)) | G10: =B10-E10 | H10: =C10-F10
A12: EN 1992-1-1 reference s: 0.20 (rapid), 0.25 (normal), 0.38 (slow) — values as quoted in report chapter 2; confirm against the standard.

Sheet LCA
A1: Block volume (m3) | B1: 0.00156
A2: Emission factors (kg CO2e per kg) — ASSUMED [Place Holder]
A3: material | B3: EF (mode) | C3: low | D3: high | E3: status
A4: cement | B4: 0.76 | C4: 0.63 | D4: 0.9 | E4: mode: Thai OPC 0.76 (Khongprom & Suwanmanee 2017); high = assumed
A5: sand | B5: 0.004 | C5: 0.002 | D5: 0.008 | E5: ASSUMED — replace with Thai LCI / TGO / ecoinvent value
A6: stone | B6: 0.005 | C6: 0.003 | D6: 0.009 | E6: ASSUMED — replace with Thai LCI / TGO / ecoinvent value
A7: rca | B7: 0.006 | C7: 0.003 | D7: 0.012 | E7: ASSUMED — replace with Thai LCI / TGO / ecoinvent value
A8: biochar | B8: 0.25 | C8: 0.05 | D8: 0.6 | E8: ASSUMED — replace with Thai LCI / TGO / ecoinvent value
A9: Carbon fraction of biochar | B9: 0.75
A10: Permanence over 100 y | B10: 0.8
A11: 44/12 | B11: =44/12
A13: mix | B13: cement g/block | C13: sand g | D13: stone g | E13: RCA g | F13: biochar g | G13: cement kg/m3 | H13: sand kg/m3 | I13: stone kg/m3 | J13: RCA kg/m3 | K13: biochar kg/m3 | L13: GWP A | M13: biochar credit | N13: GWP B | O13: cement share of A % | P13: f_c 28 d | Q13: ci A | R13: ci B | S13: bi (kg cement / m3 / MPa)
A14: NA | B14: 600 | C14: 1800 | D14: 900 | E14: 0 | F14: 0 | G14: =B14/1000/$B$1 | H14: =C14/1000/$B$1 | I14: =D14/1000/$B$1 | J14: =E14/1000/$B$1 | K14: =F14/1000/$B$1 | L14: =G14*$B$4+H14*$B$5+I14*$B$6+J14*$B$7+K14*$B$8 | M14: =K14*$B$9*$B$10*$B$11 | N14: =L14-M14 | O14: =G14*$B$4/L14*100 | P14: 91.54 | Q14: =L14/P14 | R14: =N14/P14 | S14: =G14/P14
A15: RA | B15: 600 | C15: 900 | D15: 900 | E15: 900 | F15: 0 | G15: =B15/1000/$B$1 | H15: =C15/1000/$B$1 | I15: =D15/1000/$B$1 | J15: =E15/1000/$B$1 | K15: =F15/1000/$B$1 | L15: =G15*$B$4+H15*$B$5+I15*$B$6+J15*$B$7+K15*$B$8 | M15: =K15*$B$9*$B$10*$B$11 | N15: =L15-M15 | O15: =G15*$B$4/L15*100 | P15: 60.46 | Q15: =L15/P15 | R15: =N15/P15 | S15: =G15/P15
A16: Rab5 | B16: 570 | C16: 900 | D16: 900 | E16: 900 | F16: 45 | G16: =B16/1000/$B$1 | H16: =C16/1000/$B$1 | I16: =D16/1000/$B$1 | J16: =E16/1000/$B$1 | K16: =F16/1000/$B$1 | L16: =G16*$B$4+H16*$B$5+I16*$B$6+J16*$B$7+K16*$B$8 | M16: =K16*$B$9*$B$10*$B$11 | N16: =L16-M16 | O16: =G16*$B$4/L16*100 | P16: 51.85 | Q16: =L16/P16 | R16: =N16/P16 | S16: =G16/P16
A17: Rab10 | B17: 540 | C17: 900 | D17: 900 | E17: 900 | F17: 90 | G17: =B17/1000/$B$1 | H17: =C17/1000/$B$1 | I17: =D17/1000/$B$1 | J17: =E17/1000/$B$1 | K17: =F17/1000/$B$1 | L17: =G17*$B$4+H17*$B$5+I17*$B$6+J17*$B$7+K17*$B$8 | M17: =K17*$B$9*$B$10*$B$11 | N17: =L17-M17 | O17: =G17*$B$4/L17*100 | P17: 39.37 | Q17: =L17/P17 | R17: =N17/P17 | S17: =G17/P17
A18: Rab15 | B18: 510 | C18: 900 | D18: 900 | E18: 900 | F18: 135 | G18: =B18/1000/$B$1 | H18: =C18/1000/$B$1 | I18: =D18/1000/$B$1 | J18: =E18/1000/$B$1 | K18: =F18/1000/$B$1 | L18: =G18*$B$4+H18*$B$5+I18*$B$6+J18*$B$7+K18*$B$8 | M18: =K18*$B$9*$B$10*$B$11 | N18: =L18-M18 | O18: =G18*$B$4/L18*100 | P18: 37.93 | Q18: =L18/P18 | R18: =N18/P18 | S18: =G18/P18
A19: Rab20* | B19: 480 | C19: 900 | D19: 900 | E19: 900 | F19: 180 | G19: =B19/1000/$B$1 | H19: =C19/1000/$B$1 | I19: =D19/1000/$B$1 | J19: =E19/1000/$B$1 | K19: =F19/1000/$B$1 | L19: =G19*$B$4+H19*$B$5+I19*$B$6+J19*$B$7+K19*$B$8 | M19: =K19*$B$9*$B$10*$B$11 | N19: =L19-M19 | O19: =G19*$B$4/L19*100
A20: Rab25* | B20: 450 | C20: 900 | D20: 900 | E20: 900 | F20: 225 | G20: =B20/1000/$B$1 | H20: =C20/1000/$B$1 | I20: =D20/1000/$B$1 | J20: =E20/1000/$B$1 | K20: =F20/1000/$B$1 | L20: =G20*$B$4+H20*$B$5+I20*$B$6+J20*$B$7+K20*$B$8 | M20: =K20*$B$9*$B$10*$B$11 | N20: =L20-M20 | O20: =G20*$B$4/L20*100
A21: RCA0 | B21: 600 | C21: 900 | D21: 1800 | E21: 0 | F21: 48 | G21: =B21/1000/$B$1 | H21: =C21/1000/$B$1 | I21: =D21/1000/$B$1 | J21: =E21/1000/$B$1 | K21: =F21/1000/$B$1 | L21: =G21*$B$4+H21*$B$5+I21*$B$6+J21*$B$7+K21*$B$8 | M21: =K21*$B$9*$B$10*$B$11 | N21: =L21-M21 | O21: =G21*$B$4/L21*100 | P21: 55.43 | Q21: =L21/P21 | R21: =N21/P21 | S21: =G21/P21
A22: RCA5 | B22: 600 | C22: 855 | D22: 1800 | E22: 45 | F22: 48 | G22: =B22/1000/$B$1 | H22: =C22/1000/$B$1 | I22: =D22/1000/$B$1 | J22: =E22/1000/$B$1 | K22: =F22/1000/$B$1 | L22: =G22*$B$4+H22*$B$5+I22*$B$6+J22*$B$7+K22*$B$8 | M22: =K22*$B$9*$B$10*$B$11 | N22: =L22-M22 | O22: =G22*$B$4/L22*100 | P22: 59.31 | Q22: =L22/P22 | R22: =N22/P22 | S22: =G22/P22
A23: RCA10 | B23: 600 | C23: 810 | D23: 1800 | E23: 90 | F23: 48 | G23: =B23/1000/$B$1 | H23: =C23/1000/$B$1 | I23: =D23/1000/$B$1 | J23: =E23/1000/$B$1 | K23: =F23/1000/$B$1 | L23: =G23*$B$4+H23*$B$5+I23*$B$6+J23*$B$7+K23*$B$8 | M23: =K23*$B$9*$B$10*$B$11 | N23: =L23-M23 | O23: =G23*$B$4/L23*100 | P23: 61.34 | Q23: =L23/P23 | R23: =N23/P23 | S23: =G23/P23
A24: RCA15 | B24: 600 | C24: 765 | D24: 1800 | E24: 135 | F24: 48 | G24: =B24/1000/$B$1 | H24: =C24/1000/$B$1 | I24: =D24/1000/$B$1 | J24: =E24/1000/$B$1 | K24: =F24/1000/$B$1 | L24: =G24*$B$4+H24*$B$5+I24*$B$6+J24*$B$7+K24*$B$8 | M24: =K24*$B$9*$B$10*$B$11 | N24: =L24-M24 | O24: =G24*$B$4/L24*100 | P24: 62.19 | Q24: =L24/P24 | R24: =N24/P24 | S24: =G24/P24
A27: * designed but not yet tested (no f_c). NA batch (600:1800:900) is inferred from the 1:3:1.5 ratio and is NOT printed in the draft [Place Holder].

Sheet Cost
A1: Biochar price ratio r (biochar / cement, per kg) [Place Holder] | B1: 0.5
A2: Sand/stone price (cement = 1) | B2: 0.1
A3: RCA price | B3: 0
A5: mix | B5: relative material cost (per m3) | C5: cost vs RA | D5: cost per MPa vs RA
A6: RA | B6: =LCA!G15*1+(LCA!H15+LCA!I15)*$B$2+LCA!J15*$B$3+LCA!K15*$B$1 | C6: =B6/$B$6 | D6: =(B6/LCA!P15)/($B$6/LCA!P15)
A7: Rab5 | B7: =LCA!G16*1+(LCA!H16+LCA!I16)*$B$2+LCA!J16*$B$3+LCA!K16*$B$1 | C7: =B7/$B$6 | D7: =(B7/LCA!P16)/($B$6/LCA!P15)
A8: Rab10 | B8: =LCA!G17*1+(LCA!H17+LCA!I17)*$B$2+LCA!J17*$B$3+LCA!K17*$B$1 | C8: =B8/$B$6 | D8: =(B8/LCA!P17)/($B$6/LCA!P15)
A9: Rab15 | B9: =LCA!G18*1+(LCA!H18+LCA!I18)*$B$2+LCA!J18*$B$3+LCA!K18*$B$1 | C9: =B9/$B$6 | D9: =(B9/LCA!P18)/($B$6/LCA!P15)
A11: Break-even r (Series I) = cement removed / biochar added = 30/45 = 0.667

Sheet BPN_PLACEHOLDER
A1: [Place Holder] — hypothetical BPN values; NOT measurements. 28-d anchors = the draft's example values (confirmed as examples by the researcher).
A2: series | B2: mix | C2: age_d | D2: BPN dry | E2: SD dry | F2: BPN wet | G2: SD wet | H2: dry - wet | I2: status
A3: I | B3: NA | C3: 7 | D3: 66.8 | E3: 1.7 | F3: 57.2 | G3: 2 | H3: =D3-F3 | I3: [Place Holder]
A4: I | B4: NA | C4: 14 | D4: 67.8 | E4: 1.4 | F4: 58.3 | G4: 1.5 | H4: =D4-F4 | I4: [Place Holder]
A5: I | B5: NA | C5: 28 | D5: 68.6 | E5: 1.1 | F5: 59.1 | G5: 1.8 | H5: =D5-F5 | I5: [Place Holder]
A6: I | B6: RA | C6: 7 | D6: 66.3 | E6: 1.6 | F6: 55.4 | G6: 1.9 | H6: =D6-F6 | I6: [Place Holder]
A7: I | B7: RA | C7: 14 | D7: 67.8 | E7: 1.3 | F7: 56.8 | G7: 1.4 | H7: =D7-F7 | I7: [Place Holder]
A8: I | B8: RA | C8: 28 | D8: 69.5 | E8: 1 | F8: 58.8 | G8: 1.5 | H8: =D8-F8 | I8: [Place Holder]
A9: I | B9: Rab5 | C9: 7 | D9: 65 | E9: 1.1 | F9: 56.4 | G9: 1.9 | H9: =D9-F9 | I9: [Place Holder]
A10: I | B10: Rab5 | C10: 14 | D10: 66.5 | E10: 1.5 | F10: 57.7 | G10: 1.8 | H10: =D10-F10 | I10: [Place Holder]
A11: I | B11: Rab5 | C11: 28 | D11: 67.2 | E11: 1.4 | F11: 58.2 | G11: 2.2 | H11: =D11-F11 | I11: [Place Holder]
A12: I | B12: Rab10 | C12: 7 | D12: 63.5 | E12: 1.7 | F12: 53.8 | G12: 2 | H12: =D12-F12 | I12: [Place Holder]
A13: I | B13: Rab10 | C13: 14 | D13: 65.4 | E13: 1.4 | F13: 55.5 | G13: 1.9 | H13: =D13-F13 | I13: [Place Holder]
A14: I | B14: Rab10 | C14: 28 | D14: 65.5 | E14: 1.6 | F14: 55.6 | G14: 1.4 | H14: =D14-F14 | I14: [Place Holder]
... A29: II | B29: RCA15 | C29: 28 | D29: 61.7 | E29: 1.7 | F29: 52.5 | G29: 2.1 | H29: =D29-F29 | I29: [Place Holder]
